<robot name="Xtellar.Robotics/ToGo.Prototype">

    <!-- mujoco tags for collision detection -->

    <material name="main">
        <color rgba="0.7529411764705882 0.7529411764705882 0.7529411764705882 1.0"/>
    </material>

    <!-- link tags  -->
    <link name='F_base' />

    <!-- body torso -->
    <link name="L0_body_front">
        <inertial>
            <origin xyz="-2.160440278e-03 7.391865019e-02 7.675965061e-02"
                    rpy="0.000000000e+00 0.000000000e+00 0.000000000e+00"
            />
            <mass value="1.139659386e+01" />
            <inertia ixx="1.365484540e-01" iyy="2.028016259e-01" izz="9.378844195e-02"
                     ixy="1.099460117e-05" ixz="-5.270341860e-04" iyz="5.332965063e-03"
            />
        </inertial>
        <visual>
            <origin xyz="0.000000000e+00 0.000000000e+00 0.000000000e+00"
                    rpy="0.000000000e+00 0.000000000e+00 0.000000000e+00"
            />
            <geometry>
                <mesh filename="../meshes/l0_body_front.stl" scale="1.000000000e-03 1.000000000e-03 1.000000000e-03" />
            </geometry>
            <material name="main" />
        </visual>
        <collision>
            <origin xyz="0.000000000e+00 0.000000000e+00 0.000000000e+00"
                    rpy="0.000000000e+00 0.000000000e+00 0.000000000e+00"
            />
            <geometry>
                <mesh filename="../meshes/l0_body_front.stl" scale="1.000000000e-03 1.000000000e-03 1.000000000e-03" />
            </geometry>
        </collision>
    </link>
    <link name="L1_body_rear">
        <inertial>
            <origin xyz="1.084473223e-18 3.608465643e-02 -9.648547249e-02"
                    rpy="0.000000000e+00 0.000000000e+00 0.000000000e+00"
            />
            <mass value="4.536476336e+00" />
            <inertia ixx="2.288950781e-02" iyy="4.963913835e-02" izz="3.595594733e-02"
                     ixy="3.489794068e-06" ixz="0.000000000e+00" iyz="-1.420369757e-03"
            />
        </inertial>
        <visual>
            <origin xyz="0.000000000e+00 0.000000000e+00 0.000000000e+00"
                    rpy="0.000000000e+00 0.000000000e+00 0.000000000e+00"
            />
            <geometry>
                <mesh filename="../meshes/l1_body_rear.stl" scale="1.000000000e-03 1.000000000e-03 1.000000000e-03" />
            </geometry>
            <material name="main" />
        </visual>
        <collision>
            <origin xyz="0.000000000e+00 0.000000000e+00 0.000000000e+00"
                    rpy="0.000000000e+00 0.000000000e+00 0.000000000e+00"
            />
            <geometry>
                <mesh filename="../meshes/l1_body_rear.stl" scale="1.000000000e-03 1.000000000e-03 1.000000000e-03" />
            </geometry>
        </collision>
    </link>

    <!-- front left leg -->
    <link name="Lfl1_hip_roll">
        <inertial>
            <origin xyz="-7.218781934e-04 5.949582956e-04 7.162279484e-02"
                    rpy="0.000000000e+00 0.000000000e+00 0.000000000e+00"
            />
            <mass value="1.887043626e+00" />
            <inertia ixx="3.748543127e-03" iyy="2.915061831e-03" izz="2.089010486e-03"
                     ixy="3.359890495e-05" ixz="-2.521507038e-05" iyz="-2.475313699e-05"
            />
        </inertial>
        <visual>
            <origin xyz="0.000000000e+00 0.000000000e+00 0.000000000e+00"
                    rpy="0.000000000e+00 0.000000000e+00 0.000000000e+00"
            />
            <geometry>
                <mesh filename="../meshes/lfl1_hip_roll.stl" scale="1.000000000e-03 1.000000000e-03 1.000000000e-03" />
            </geometry>
            <material name="main" />
        </visual>
        <collision>
            <origin xyz="0.000000000e+00 0.000000000e+00 0.000000000e+00"
                    rpy="0.000000000e+00 0.000000000e+00 0.000000000e+00"
            />
            <geometry>
                <mesh filename="../meshes/lfl1_hip_roll.stl" scale="1.000000000e-03 1.000000000e-03 1.000000000e-03" />
            </geometry>
        </collision>
    </link>
    <link name="Lfl2_hip_pitch">
        <inertial>
            <origin xyz="6.346748536e-02 4.844918472e-03 -4.638462066e-02"
                    rpy="0.000000000e+00 0.000000000e+00 0.000000000e+00"
            />
            <mass value="3.023532673e+00" />
            <inertia ixx="3.172443996e-02" iyy="3.242234462e-02" izz="6.362320073e-03"
                     ixy="-5.838623889e-04" ixz="5.373137003e-03" iyz="1.632961065e-03"
            />
        </inertial>
        <visual>
            <origin xyz="0.000000000e+00 0.000000000e+00 0.000000000e+00"
                    rpy="0.000000000e+00 0.000000000e+00 0.000000000e+00"
            />
            <geometry>
                <mesh filename="../meshes/lfl2_hip_pitch.stl" scale="1.000000000e-03 1.000000000e-03 1.000000000e-03" />
            </geometry>
            <material name="main" />
        </visual>
        <collision>
            <origin xyz="0.000000000e+00 0.000000000e+00 0.000000000e+00"
                    rpy="0.000000000e+00 0.000000000e+00 0.000000000e+00"
            />
            <geometry>
                <mesh filename="../meshes/lfl2_hip_pitch.stl" scale="1.000000000e-03 1.000000000e-03 1.000000000e-03" />
            </geometry>
        </collision>
    </link>
    <link name="Lfl3_knee">
        <inertial>
            <origin xyz="1.263152507e-02 -1.463381461e-01 1.896785452e-01"
                    rpy="0.000000000e+00 0.000000000e+00 0.000000000e+00"
            />
            <mass value="1.590219164e+00" />
            <inertia ixx="1.987810147e-02" iyy="1.249170801e-02" izz="8.346688455e-03"
                     ixy="8.375368726e-04" ixz="-1.012803121e-03" iyz="8.824097408e-03"
            />
        </inertial>
        <visual>
            <origin xyz="0.000000000e+00 0.000000000e+00 0.000000000e+00"
                    rpy="0.000000000e+00 0.000000000e+00 0.000000000e+00"
            />
            <geometry>
                <mesh filename="../meshes/lfl3_knee.stl" scale="1.000000000e-03 1.000000000e-03 1.000000000e-03" />
            </geometry>
            <material name="main" />
        </visual>
        <collision>
            <origin xyz="0.000000000e+00 0.000000000e+00 0.000000000e+00"
                    rpy="0.000000000e+00 0.000000000e+00 0.000000000e+00"
            />
            <geometry>
                <mesh filename="../meshes/lfl3_knee.stl" scale="1.000000000e-03 1.000000000e-03 1.000000000e-03" />
            </geometry>
        </collision>
    </link>
    <link name="Lfl4_wheel">
        <inertial>
            <origin xyz="9.771946597e-03 4.078350782e-09 -1.664886526e-08"
                    rpy="0.000000000e+00 0.000000000e+00 0.000000000e+00"
            />
            <mass value="1.292573765e+00" />
            <inertia ixx="5.526587828e-03" iyy="2.904900666e-03" izz="2.904865502e-03"
                     ixy="9.806179590e-14" ixz="1.929721917e-13" iyz="7.217850448e-24"
            />
        </inertial>
        <visual>
            <origin xyz="0.000000000e+00 0.000000000e+00 0.000000000e+00"
                    rpy="0.000000000e+00 0.000000000e+00 0.000000000e+00"
            />
            <geometry>
                <mesh filename="../meshes/lfl4_wheel.stl" scale="1.000000000e-03 1.000000000e-03 1.000000000e-03" />
            </geometry>
            <material name="main" />
        </visual>
        <collision>
            <origin xyz="0.000000000e+00 0.000000000e+00 0.000000000e+00"
                    rpy="0.000000000e+00 0.000000000e+00 0.000000000e+00"
            />
            <geometry>
                <mesh filename="../meshes/lfl4_wheel.stl" scale="1.000000000e-03 1.000000000e-03 1.000000000e-03" />
            </geometry>
        </collision>
    </link>

    <!-- front right leg -->
    <link name="Lfr1_hip_roll">
        <inertial>
            <origin xyz="7.144685036e-04 5.962087688e-04 7.137999600e-02"
                    rpy="0.000000000e+00 0.000000000e+00 0.000000000e+00"
            />
            <mass value="1.894140161e+00" />
            <inertia ixx="3.779979220e-03" iyy="2.947083450e-03" izz="2.092282368e-03"
                     ixy="-3.345744103e-05" ixz="2.512586225e-05" iyz="-2.472469088e-05"
            />
        </inertial>
        <visual>
            <origin xyz="0.000000000e+00 0.000000000e+00 0.000000000e+00"
                    rpy="0.000000000e+00 0.000000000e+00 0.000000000e+00"
            />
            <geometry>
                <mesh filename="../meshes/lfr1_hip_roll.stl" scale="1.000000000e-03 1.000000000e-03 1.000000000e-03" />
            </geometry>
            <material name="main" />
        </visual>
        <collision>
            <origin xyz="0.000000000e+00 0.000000000e+00 0.000000000e+00"
                    rpy="0.000000000e+00 0.000000000e+00 0.000000000e+00"
            />
            <geometry>
                <mesh filename="../meshes/lfr1_hip_roll.stl" scale="1.000000000e-03 1.000000000e-03 1.000000000e-03" />
            </geometry>
        </collision>
    </link>
    <link name="Lfr2_hip_pitch">
        <inertial>
            <origin xyz="-6.347362217e-02 4.845879513e-03 -4.638229906e-02"
                    rpy="0.000000000e+00 0.000000000e+00 0.000000000e+00"
            />
            <mass value="3.023536580e+00" />
            <inertia ixx="3.172086952e-02" iyy="3.242099324e-02" izz="6.364486562e-03"
                     ixy="5.838902334e-04" ixz="-5.374138070e-03" iyz="1.632835155e-03"
            />
        </inertial>
        <visual>
            <origin xyz="0.000000000e+00 0.000000000e+00 0.000000000e+00"
                    rpy="0.000000000e+00 0.000000000e+00 0.000000000e+00"
            />
            <geometry>
                <mesh filename="../meshes/lfr2_hip_pitch.stl" scale="1.000000000e-03 1.000000000e-03 1.000000000e-03" />
            </geometry>
            <material name="main" />
        </visual>
        <collision>
            <origin xyz="0.000000000e+00 0.000000000e+00 0.000000000e+00"
                    rpy="0.000000000e+00 0.000000000e+00 0.000000000e+00"
            />
            <geometry>
                <mesh filename="../meshes/lfr2_hip_pitch.stl" scale="1.000000000e-03 1.000000000e-03 1.000000000e-03" />
            </geometry>
        </collision>
    </link>
    <link name="Lfr3_knee">
        <inertial>
            <origin xyz="-1.263152424e-02 -1.462987283e-01 1.897041425e-01"
                    rpy="0.000000000e+00 0.000000000e+00 0.000000000e+00"
            />
            <mass value="1.590219198e+00" />
            <inertia ixx="1.987709300e-02" iyy="1.249560477e-02" izz="8.341783311e-03"
                     ixy="-8.387570080e-04" ixz="1.012010778e-03" iyz="8.822690073e-03"
            />
        </inertial>
        <visual>
            <origin xyz="0.000000000e+00 0.000000000e+00 0.000000000e+00"
                    rpy="0.000000000e+00 0.000000000e+00 0.000000000e+00"
            />
            <geometry>
                <mesh filename="../meshes/lfr3_knee.stl" scale="1.000000000e-03 1.000000000e-03 1.000000000e-03" />
            </geometry>
            <material name="main" />
        </visual>
        <collision>
            <origin xyz="0.000000000e+00 0.000000000e+00 0.000000000e+00"
                    rpy="0.000000000e+00 0.000000000e+00 0.000000000e+00"
            />
            <geometry>
                <mesh filename="../meshes/lfr3_knee.stl" scale="1.000000000e-03 1.000000000e-03 1.000000000e-03" />
            </geometry>
        </collision>
    </link>
    <link name="Lfr4_wheel">
        <inertial>
            <origin xyz="-9.771946597e-03 1.049721249e-08 1.355106480e-08"
                    rpy="0.000000000e+00 0.000000000e+00 0.000000000e+00"
            />
            <mass value="1.292573765e+00" />
            <inertia ixx="5.526587828e-03" iyy="2.904903074e-03" izz="2.904863094e-03"
                     ixy="8.384166721e-19" ixz="3.216355069e-19" iyz="-2.465190329e-32"
            />
        </inertial>
        <visual>
            <origin xyz="0.000000000e+00 0.000000000e+00 0.000000000e+00"
                    rpy="0.000000000e+00 0.000000000e+00 0.000000000e+00"
            />
            <geometry>
                <mesh filename="../meshes/lfr4_wheel.stl" scale="1.000000000e-03 1.000000000e-03 1.000000000e-03" />
            </geometry>
            <material name="main" />
        </visual>
        <collision>
            <origin xyz="0.000000000e+00 0.000000000e+00 0.000000000e+00"
                    rpy="0.000000000e+00 0.000000000e+00 0.000000000e+00"
            />
            <geometry>
                <mesh filename="../meshes/lfr4_wheel.stl" scale="1.000000000e-03 1.000000000e-03 1.000000000e-03" />
            </geometry>
        </collision>
    </link>

    <!-- rear left leg -->
    <link name="Lrl1_hip_roll">
        <inertial>
            <origin xyz="-7.144685036e-04 5.962087688e-04 -7.137999600e-02"
                    rpy="0.000000000e+00 0.000000000e+00 0.000000000e+00"
            />
            <mass value="1.894140161e+00" />
            <inertia ixx="3.779979220e-03" iyy="2.947083450e-03" izz="2.092282368e-03"
                     ixy="3.345744103e-05" ixz="2.512586225e-05" iyz="2.472469088e-05"
            />
        </inertial>
        <visual>
            <origin xyz="0.000000000e+00 0.000000000e+00 0.000000000e+00"
                    rpy="0.000000000e+00 0.000000000e+00 0.000000000e+00"
            />
            <geometry>
                <mesh filename="../meshes/lrl1_hip_roll.stl" scale="1.000000000e-03 1.000000000e-03 1.000000000e-03" />
            </geometry>
            <material name="main" />
        </visual>
        <collision>
            <origin xyz="0.000000000e+00 0.000000000e+00 0.000000000e+00"
                    rpy="0.000000000e+00 0.000000000e+00 0.000000000e+00"
            />
            <geometry>
                <mesh filename="../meshes/lrl1_hip_roll.stl" scale="1.000000000e-03 1.000000000e-03 1.000000000e-03" />
            </geometry>
        </collision>
    </link>
    <link name="Lrl2_hip_pitch">
        <inertial>
            <origin xyz="6.346748536e-02 4.845918553e-03 -4.464742773e-02"
                    rpy="0.000000000e+00 0.000000000e+00 0.000000000e+00"
            />
            <mass value="3.023532673e+00" />
            <inertia ixx="3.220255281e-02" iyy="3.290048678e-02" izz="6.362290769e-03"
                     ixy="-5.837432177e-04" ixz="5.588807339e-03" iyz="1.658273799e-03"
            />
        </inertial>
        <visual>
            <origin xyz="0.000000000e+00 0.000000000e+00 0.000000000e+00"
                    rpy="0.000000000e+00 0.000000000e+00 0.000000000e+00"
            />
            <geometry>
                <mesh filename="../meshes/lrl2_hip_pitch.stl" scale="1.000000000e-03 1.000000000e-03 1.000000000e-03" />
            </geometry>
            <material name="main" />
        </visual>
        <collision>
            <origin xyz="0.000000000e+00 0.000000000e+00 0.000000000e+00"
                    rpy="0.000000000e+00 0.000000000e+00 0.000000000e+00"
            />
            <geometry>
                <mesh filename="../meshes/lrl2_hip_pitch.stl" scale="1.000000000e-03 1.000000000e-03 1.000000000e-03" />
            </geometry>
        </collision>
    </link>
    <link name="Lrl3_knee">
        <inertial>
            <origin xyz="1.263152507e-02 -1.463381536e-01 1.896785394e-01"
                    rpy="0.000000000e+00 0.000000000e+00 0.000000000e+00"
            />
            <mass value="1.590219164e+00" />
            <inertia ixx="1.987810147e-02" iyy="1.249170731e-02" izz="8.346689155e-03"
                     ixy="8.375369127e-04" ixz="-1.012803088e-03" iyz="8.824097573e-03"
            />
        </inertial>
        <visual>
            <origin xyz="0.000000000e+00 0.000000000e+00 0.000000000e+00"
                    rpy="0.000000000e+00 0.000000000e+00 0.000000000e+00"
            />
            <geometry>
                <mesh filename="../meshes/lrl3_knee.stl" scale="1.000000000e-03 1.000000000e-03 1.000000000e-03" />
            </geometry>
            <material name="main" />
        </visual>
        <collision>
            <origin xyz="0.000000000e+00 0.000000000e+00 0.000000000e+00"
                    rpy="0.000000000e+00 0.000000000e+00 0.000000000e+00"
            />
            <geometry>
                <mesh filename="../meshes/lrl3_knee.stl" scale="1.000000000e-03 1.000000000e-03 1.000000000e-03" />
            </geometry>
        </collision>
    </link>
    <link name="Lrl4_wheel">
        <inertial>
            <origin xyz="9.771946596e-03 -4.792935021e-09 -1.645753933e-08"
                    rpy="0.000000000e+00 0.000000000e+00 0.000000000e+00"
            />
            <mass value="1.292573765e+00" />
            <inertia ixx="5.526587829e-03" iyy="2.904882290e-03" izz="2.904883879e-03"
                     ixy="-1.112179803e-15" ixz="-1.668933033e-15" iyz="7.080026624e-28"
            />
        </inertial>
        <visual>
            <origin xyz="0.000000000e+00 0.000000000e+00 0.000000000e+00"
                    rpy="0.000000000e+00 0.000000000e+00 0.000000000e+00"
            />
            <geometry>
                <mesh filename="../meshes/lrl4_wheel.stl" scale="1.000000000e-03 1.000000000e-03 1.000000000e-03" />
            </geometry>
            <material name="main" />
        </visual>
        <collision>
            <origin xyz="0.000000000e+00 0.000000000e+00 0.000000000e+00"
                    rpy="0.000000000e+00 0.000000000e+00 0.000000000e+00"
            />
            <geometry>
                <mesh filename="../meshes/lrl4_wheel.stl" scale="1.000000000e-03 1.000000000e-03 1.000000000e-03" />
            </geometry>
        </collision>
    </link>

    <!-- rear right leg -->
    <link name="Lrr1_hip_roll">
        <inertial>
            <origin xyz="7.218781934e-04 5.949582956e-04 -7.162279484e-02"
                    rpy="0.000000000e+00 0.000000000e+00 0.000000000e+00"
            />
            <mass value="1.887043626e+00" />
            <inertia ixx="3.748543127e-03" iyy="2.915061831e-03" izz="2.089010486e-03"
                     ixy="-3.359890495e-05" ixz="-2.521507038e-05" iyz="2.475313699e-05"
            />
        </inertial>
        <visual>
            <origin xyz="0.000000000e+00 0.000000000e+00 0.000000000e+00"
                    rpy="0.000000000e+00 0.000000000e+00 0.000000000e+00"
            />
            <geometry>
                <mesh filename="../meshes/lrr1_hip_roll.stl" scale="1.000000000e-03 1.000000000e-03 1.000000000e-03" />
            </geometry>
            <material name="main" />
        </visual>
        <collision>
            <origin xyz="0.000000000e+00 0.000000000e+00 0.000000000e+00"
                    rpy="0.000000000e+00 0.000000000e+00 0.000000000e+00"
            />
            <geometry>
                <mesh filename="../meshes/lrr1_hip_roll.stl" scale="1.000000000e-03 1.000000000e-03 1.000000000e-03" />
            </geometry>
        </collision>
    </link>
    <link name="Lrr2_hip_pitch">
        <inertial>
            <origin xyz="-6.347362217e-02 4.844880184e-03 -4.464510837e-02"
                    rpy="0.000000000e+00 0.000000000e+00 0.000000000e+00"
            />
            <mass value="3.023536580e+00" />
            <inertia ixx="3.219901671e-02" iyy="3.289911101e-02" izz="6.364515980e-03"
                     ixy="5.840095199e-04" ixz="-5.589840639e-03" iyz="1.658423400e-03"
            />
        </inertial>
        <visual>
            <origin xyz="0.000000000e+00 0.000000000e+00 0.000000000e+00"
                    rpy="0.000000000e+00 0.000000000e+00 0.000000000e+00"
            />
            <geometry>
                <mesh filename="../meshes/lrr2_hip_pitch.stl" scale="1.000000000e-03 1.000000000e-03 1.000000000e-03" />
            </geometry>
            <material name="main" />
        </visual>
        <collision>
            <origin xyz="0.000000000e+00 0.000000000e+00 0.000000000e+00"
                    rpy="0.000000000e+00 0.000000000e+00 0.000000000e+00"
            />
            <geometry>
                <mesh filename="../meshes/lrr2_hip_pitch.stl" scale="1.000000000e-03 1.000000000e-03 1.000000000e-03" />
            </geometry>
        </collision>
    </link>
    <link name="Lrr3_knee">
        <inertial>
            <origin xyz="-1.270152424e-02 -1.462987283e-01 1.897041425e-01"
                    rpy="0.000000000e+00 0.000000000e+00 0.000000000e+00"
            />
            <mass value="1.590219198e+00" />
            <inertia ixx="1.987709300e-02" iyy="1.249560477e-02" izz="8.341783311e-03"
                     ixy="-8.387570080e-04" ixz="1.012010778e-03" iyz="8.822690073e-03"
            />
        </inertial>
        <visual>
            <origin xyz="0.000000000e+00 0.000000000e+00 0.000000000e+00"
                    rpy="0.000000000e+00 0.000000000e+00 0.000000000e+00"
            />
            <geometry>
                <mesh filename="../meshes/lrr3_knee.stl" scale="1.000000000e-03 1.000000000e-03 1.000000000e-03" />
            </geometry>
            <material name="main" />
        </visual>
        <collision>
            <origin xyz="0.000000000e+00 0.000000000e+00 0.000000000e+00"
                    rpy="0.000000000e+00 0.000000000e+00 0.000000000e+00"
            />
            <geometry>
                <mesh filename="../meshes/lrr3_knee.stl" scale="1.000000000e-03 1.000000000e-03 1.000000000e-03" />
            </geometry>
        </collision>
    </link>
    <link name="Lrr4_wheel">
        <inertial>
            <origin xyz="-9.771946596e-03 -1.586638509e-08 -6.486960136e-09"
                    rpy="0.000000000e+00 0.000000000e+00 0.000000000e+00"
            />
            <mass value="1.292573765e+00" />
            <inertia ixx="5.526587829e-03" iyy="2.904888178e-03" izz="2.904877991e-03"
                     ixy="-1.801139669e-18" ixz="-1.207949219e-18" iyz="0.000000000e+00"
            />
        </inertial>
        <visual>
            <origin xyz="0.000000000e+00 0.000000000e+00 0.000000000e+00"
                    rpy="0.000000000e+00 0.000000000e+00 0.000000000e+00"
            />
            <geometry>
                <mesh filename="../meshes/lrr4_wheel.stl" scale="1.000000000e-03 1.000000000e-03 1.000000000e-03" />
            </geometry>
            <material name="main" />
        </visual>
        <collision>
            <origin xyz="0.000000000e+00 0.000000000e+00 0.000000000e+00"
                    rpy="0.000000000e+00 0.000000000e+00 0.000000000e+00"
            />
            <geometry>
                <mesh filename="../meshes/lrr4_wheel.stl" scale="1.000000000e-03 1.000000000e-03 1.000000000e-03" />
            </geometry>
        </collision>
    </link>


    <!-- joint tags  -->

    <!-- body torso -->
    <joint name="J_F_base_L0_body_front" type="fixed">
        <origin xyz="0.000000000e+00 0.000000000e+00 2.000000000e-01"
                rpy="1.570796327e+00 0.000000000e+00 1.570796327e+00"
        />
        <parent link="F_base" />
        <child link="L0_body_front" />
    </joint>
    <joint name="J1_waist" type="revolute">
        <origin xyz="0.000000000e+00 3.325000000e-02 -8.000000000e-02"
                rpy="0.000000000e+00 0.000000000e+00 0.000000000e+00"
        />
        <parent link="L0_body_front" />
        <child link="L1_body_rear" />
        <axis xyz="0.000000000e+00 -1.000000000e+00 0.000000000e+00" />
        <dynamics damping="1.368000000e-02" friction="1.000000000e-01"/>
        <limit lower="-0.026179938779914945" upper="0.026179938779914945" effort="97.0" velocity="6.283185307179586" />
    </joint>

    <!-- front left leg -->
    <joint name="Jfl1_hip_roll" type="revolute">
        <origin xyz="9.000000000e-02 7.500000000e-02 1.870000000e-01"
                rpy="0.000000000e+00 0.000000000e+00 0.000000000e+00"
        />
        <parent link="L0_body_front" />
        <child link="Lfl1_hip_roll" />
        <axis xyz="0.000000000e+00 0.000000000e+00 1.000000000e+00" />
        <dynamics damping="2.700000000e-02" friction="1.000000000e-01"/>
        <limit lower="-1.0471975511965976" upper="1.0471975511965976" effort="150.0" velocity="15.707963267948966" />
    </joint>
    <joint name="Jfl2_hip_pitch" type="revolute">
        <origin xyz="2.600000000e-02 0.000000000e+00 7.300000000e-02"
                rpy="0.000000000e+00 0.000000000e+00 0.000000000e+00"
        />
        <parent link="Lfl1_hip_roll" />
        <child link="Lfl2_hip_pitch" />
        <axis xyz="1.000000000e+00 0.000000000e+00 0.000000000e+00" />
        <dynamics damping="2.700000000e-02" friction="1.000000000e-01"/>
        <limit lower="-1.5707963267948966" upper="1.5707963267948966" effort="150.0" velocity="15.707963267948966" />
    </joint>
    <joint name="Jfl3_knee" type="revolute">
        <origin xyz="1.059700000e-01 0.000000000e+00 -3.000000000e-01"
                rpy="0.000000000e+00 0.000000000e+00 0.000000000e+00"
        />
        <parent link="Lfl2_hip_pitch" />
        <child link="Lfl3_knee" />
        <axis xyz="1.000000000e+00 0.000000000e+00 0.000000000e+00" />
        <dynamics damping="2.700000000e-02" friction="1.000000000e-01"/>
        <limit lower="-0.17453292519943295" upper="1.5707963267948966" effort="150.0" velocity="15.707963267948966" />
    </joint>
    <joint name="Jfl4_wheel" type="continuous">
        <origin xyz="5.130000000e-02 -1.846984332e-01 2.364032334e-01"
                rpy="0.000000000e+00 0.000000000e+00 0.000000000e+00"
        />
        <parent link="Lfl3_knee" />
        <child link="Lfl4_wheel" />
        <axis xyz="1.000000000e+00 0.000000000e+00 0.000000000e+00" />
        <dynamics damping="1.380000000e-02" friction="1.000000000e-01"/>
        <limit lower="0.0" upper="0.0" effort="40.0" velocity="33.510321638291124" />
    </joint>

    <!-- front right leg -->
    <joint name="Jfr1_hip_roll" type="revolute">
        <origin xyz="-9.000000000e-02 7.500000000e-02 1.870000000e-01"
                rpy="0.000000000e+00 0.000000000e+00 0.000000000e+00"
        />
        <parent link="L0_body_front" />
        <child link="Lfr1_hip_roll" />
        <axis xyz="0.000000000e+00 0.000000000e+00 1.000000000e+00" />
        <dynamics damping="2.700000000e-02" friction="1.000000000e-01"/>
        <limit lower="-1.0471975511965976" upper="1.0471975511965976" effort="150.0" velocity="15.707963267948966" />
    </joint>
    <joint name="Jfr2_hip_pitch" type="revolute">
        <origin xyz="-2.600000000e-02 0.000000000e+00 7.300000000e-02"
                rpy="0.000000000e+00 0.000000000e+00 0.000000000e+00"
        />
        <parent link="Lfr1_hip_roll" />
        <child link="Lfr2_hip_pitch" />
        <axis xyz="-1.000000000e+00 0.000000000e+00 0.000000000e+00" />
        <dynamics damping="2.700000000e-02" friction="1.000000000e-01"/>
        <limit lower="-1.5707963267948966" upper="1.5707963267948966" effort="150.0" velocity="15.707963267948966" />
    </joint>
    <joint name="Jfr3_knee" type="revolute">
        <origin xyz="-1.060000000e-01 0.000000000e+00 -3.000000000e-01"
                rpy="0.000000000e+00 0.000000000e+00 0.000000000e+00"
        />
        <parent link="Lfr2_hip_pitch" />
        <child link="Lfr3_knee" />
        <axis xyz="-1.000000000e+00 0.000000000e+00 0.000000000e+00" />
        <dynamics damping="2.700000000e-02" friction="1.000000000e-01"/>
        <limit lower="-1.5707963267948966" upper="0.17453292519943295" effort="150.0" velocity="15.707963267948966" />
    </joint>
    <joint name="Jfr4_wheel" type="continuous">
        <origin xyz="-5.130000000e-02 -1.846984426e-01 2.364032261e-01"
                rpy="0.000000000e+00 0.000000000e+00 0.000000000e+00"
        />
        <parent link="Lfr3_knee" />
        <child link="Lfr4_wheel" />
        <axis xyz="-1.000000000e+00 0.000000000e+00 0.000000000e+00" />
        <dynamics damping="1.380000000e-02" friction="1.000000000e-01"/>
        <limit lower="0.0" upper="0.0" effort="40.0" velocity="33.510321638291124" />
    </joint>

    <!-- rear left leg -->
    <joint name="Jrl1_hip_roll" type="revolute">
        <origin xyz="9.000000000e-02 4.175000000e-02 -1.070000000e-01"
                rpy="0.000000000e+00 0.000000000e+00 0.000000000e+00"
        />
        <parent link="L1_body_rear" />
        <child link="Lrl1_hip_roll" />
        <axis xyz="0.000000000e+00 0.000000000e+00 -1.000000000e+00" />
        <dynamics damping="2.700000000e-02" friction="1.000000000e-01"/>
        <limit lower="-1.0471975511965976" upper="1.0471975511965976" effort="150.0" velocity="15.707963267948966" />
    </joint>
    <joint name="Jrl2_hip_pitch" type="revolute">
        <origin xyz="2.600000000e-02 0.000000000e+00 -7.300000000e-02"
                rpy="0.000000000e+00 0.000000000e+00 0.000000000e+00"
        />
        <parent link="Lrl1_hip_roll" />
        <child link="Lrl2_hip_pitch" />
        <axis xyz="1.000000000e+00 0.000000000e+00 0.000000000e+00" />
        <dynamics damping="2.700000000e-02" friction="1.000000000e-01"/>
        <limit lower="-1.5707963267948966" upper="1.5707963267948966" effort="150.0" velocity="15.707963267948966" />
    </joint>
    <joint name="Jrl3_knee" type="revolute">
        <origin xyz="1.060000000e-01 0.000000000e+00 -3.000000000e-01"
                rpy="0.000000000e+00 0.000000000e+00 0.000000000e+00"
        />
        <parent link="Lrl2_hip_pitch" />
        <child link="Lrl3_knee" />
        <axis xyz="1.000000000e+00 0.000000000e+00 0.000000000e+00" />
        <dynamics damping="2.700000000e-02" friction="1.000000000e-01"/>
        <limit lower="-0.17453292519943295" upper="1.5707963267948966" effort="150.0" velocity="15.707963267948966" />
    </joint>
    <joint name="Jrl4_wheel" type="continuous">
        <origin xyz="5.130000000e-02 -1.846984426e-01 2.364032261e-01"
                rpy="0.000000000e+00 0.000000000e+00 0.000000000e+00"
        />
        <parent link="Lrl3_knee" />
        <child link="Lrl4_wheel" />
        <axis xyz="1.000000000e+00 0.000000000e+00 0.000000000e+00" />
        <dynamics damping="1.380000000e-02" friction="1.000000000e-01"/>
        <limit lower="0.0" upper="0.0" effort="40.0" velocity="33.510321638291124" />
    </joint>

    <!-- rear left leg -->
    <joint name="Jrr1_hip_roll" type="revolute">
        <origin xyz="-9.000000000e-02 4.175000000e-02 -1.070000000e-01"
                rpy="0.000000000e+00 0.000000000e+00 0.000000000e+00"
        />
        <parent link="L1_body_rear" />
        <child link="Lrr1_hip_roll" />
        <axis xyz="0.000000000e+00 0.000000000e+00 -1.000000000e+00" />
        <dynamics damping="2.700000000e-02" friction="1.000000000e-01"/>
        <limit lower="-1.0471975511965976" upper="1.0471975511965976" effort="150.0" velocity="15.707963267948966" />
    </joint>
    <joint name="Jrr2_hip_pitch" type="revolute">
        <origin xyz="-2.600000000e-02 0.000000000e+00 -7.300000000e-02"
                rpy="0.000000000e+00 0.000000000e+00 0.000000000e+00"
        />
        <parent link="Lrr1_hip_roll" />
        <child link="Lrr2_hip_pitch" />
        <axis xyz="-1.000000000e+00 0.000000000e+00 0.000000000e+00" />
        <dynamics damping="2.700000000e-02" friction="1.000000000e-01"/>
        <limit lower="-1.5707963267948966" upper="1.5707963267948966" effort="150.0" velocity="15.707963267948966" />
    </joint>
    <joint name="Jrr3_knee" type="revolute">
        <origin xyz="-1.060000000e-01 0.000000000e+00 -3.000000000e-01"
                rpy="0.000000000e+00 0.000000000e+00 0.000000000e+00"
        />
        <parent link="Lrr2_hip_pitch" />
        <child link="Lrr3_knee" />
        <axis xyz="-1.000000000e+00 0.000000000e+00 0.000000000e+00" />
        <dynamics damping="2.700000000e-02" friction="1.000000000e-01"/>
        <limit lower="-1.5707963267948966" upper="0.17453292519943295" effort="150.0" velocity="15.707963267948966" />
    </joint>
    <joint name="Jrr4_wheel" type="continuous">
        <origin xyz="-5.137000000e-02 -1.846984426e-01 2.364032261e-01"
                rpy="0.000000000e+00 0.000000000e+00 0.000000000e+00"
        />
        <parent link="Lrr3_knee" />
        <child link="Lrr4_wheel" />
        <axis xyz="-1.000000000e+00 0.000000000e+00 0.000000000e+00" />
        <dynamics damping="1.380000000e-02" friction="1.000000000e-01"/>
        <limit lower="0.0" upper="0.0" effort="40.0" velocity="33.510321638291124" />
    </joint>

</robot>
