<robot name='XtellarRobotics/ToGo_F_v1p0'>

    <!-- mujoco tags -->

    <material name="main">
        <color rgba="0.7529411764705882 0.7529411764705882 0.7529411764705882 1.0"/>
    </material>
    <material name="rubber_foot">
        <color rgba="0.149 0.149 0.149 1.0"/>
    </material>

    <!-- link tags  -->

    <link name='F_base' />
    <link name='F_imu' />
    <link name="L0_torso">
        <inertial>
            <origin xyz="1.131547440e-03 9.841589053e-05 9.962489480e-02"
                    rpy="0.000000000e+00 0.000000000e+00 0.000000000e+00"
            />
            <mass value="2.053698184e+01" />
            <inertia ixx="1.302143322e+00" iyy="1.812976889e+00" izz="1.957956105e+00"
                     ixy="-6.713412039e-04" ixz="-2.586295210e-03" iyz="-1.006414943e-03"
            />
        </inertial>
        <visual>
            <origin xyz="0.000000000e+00 0.000000000e+00 0.000000000e+00"
                    rpy="0.000000000e+00 0.000000000e+00 0.000000000e+00"
            />
            <geometry>
                <mesh filename="../meshes/m0_torso.stl" scale="1.000000000e-03 1.000000000e-03 1.000000000e-03" />
            </geometry>
            <material name="main" />
        </visual>
        <collision>
            <origin xyz="0.000000000e+00 0.000000000e+00 0.000000000e+00"
                    rpy="0.000000000e+00 0.000000000e+00 0.000000000e+00"
            />
            <geometry>
                <mesh filename="../meshes/m0_torso.stl" scale="1.000000000e-03 1.000000000e-03 1.000000000e-03" />
            </geometry>
        </collision>
    </link>
    <!-- front left leg -->
    <link name="Lfl1_hipr">
        <inertial>
            <origin xyz="7.294080095e-02 3.134129647e-02 8.641283195e-04"
                    rpy="0.000000000e+00 0.000000000e+00 0.000000000e+00"
            />
            <mass value="2.427425827e+00" />
            <inertia ixx="2.546407316e-03" iyy="3.454061042e-03" izz="3.163154640e-03"
                     ixy="-4.352991409e-04" ixz="4.536943161e-05" iyz="-3.739923718e-05"
            />
        </inertial>
        <visual>
            <origin xyz="0.000000000e+00 0.000000000e+00 0.000000000e+00"
                    rpy="0.000000000e+00 0.000000000e+00 0.000000000e+00"
            />
            <geometry>
                <mesh filename="../meshes/mfl1_hipr.stl" scale="1.000000000e-03 1.000000000e-03 1.000000000e-03" />
            </geometry>
            <material name="main" />
        </visual>
        <collision>
            <origin xyz="0.000000000e+00 0.000000000e+00 0.000000000e+00"
                    rpy="0.000000000e+00 0.000000000e+00 0.000000000e+00"
            />
            <geometry>
                <mesh filename="../meshes/mfl1_hipr.stl" scale="1.000000000e-03 1.000000000e-03 1.000000000e-03" />
            </geometry>
        </collision>
    </link>
    <link name="Lfl2_hipp">
        <inertial>
            <origin xyz="-2.532435474e-03 4.503664901e-02 -1.957866607e-01"
                    rpy="0.000000000e+00 0.000000000e+00 0.000000000e+00"
            />
            <mass value="2.594676127e+00" />
            <inertia ixx="2.316445599e-02" iyy="2.390815237e-02" izz="2.153703155e-03"
                     ixy="-8.660442215e-05" ixz="6.522667705e-04" iyz="2.473164296e-03"
            />
        </inertial>
        <visual>
            <origin xyz="0.000000000e+00 0.000000000e+00 0.000000000e+00"
                    rpy="0.000000000e+00 0.000000000e+00 0.000000000e+00"
            />
            <geometry>
                <mesh filename="../meshes/mfl2_hipp.stl" scale="1.000000000e-03 1.000000000e-03 1.000000000e-03" />
            </geometry>
            <material name="main" />
        </visual>
        <collision>
            <origin xyz="0.000000000e+00 0.000000000e+00 0.000000000e+00"
                    rpy="0.000000000e+00 0.000000000e+00 0.000000000e+00"
            />
            <geometry>
                <mesh filename="../meshes/mfl2_hipp.stl" scale="1.000000000e-03 1.000000000e-03 1.000000000e-03" />
            </geometry>
        </collision>
    </link>
    <link name="Lfl3_knee">
        <inertial>
            <origin xyz="2.426553019e-02 -1.042500691e-02 -1.612786530e-01"
                    rpy="0.000000000e+00 0.000000000e+00 0.000000000e+00"
            />
            <mass value="6.285872676e-01" />
            <inertia ixx="1.035529753e-02" iyy="1.066728763e-02" izz="4.117758631e-04"
                     ixy="-6.811911601e-06" ixz="9.613583800e-04" iyz="4.584135263e-05"
            />
        </inertial>
        <visual>
            <origin xyz="0.000000000e+00 0.000000000e+00 0.000000000e+00"
                    rpy="0.000000000e+00 0.000000000e+00 0.000000000e+00"
            />
            <geometry>
                <mesh filename="../meshes/mfl3_knee.stl" scale="1.000000000e-03 1.000000000e-03 1.000000000e-03" />
            </geometry>
            <material name="main" />
        </visual>
        <collision>
            <origin xyz="0.000000000e+00 0.000000000e+00 0.000000000e+00"
                    rpy="0.000000000e+00 0.000000000e+00 0.000000000e+00"
            />
            <geometry>
                <mesh filename="../meshes/mfl3_knee.stl" scale="1.000000000e-03 1.000000000e-03 1.000000000e-03" />
            </geometry>
        </collision>
    </link>
    <link name="Lfl4_foot">
        <inertial>
            <origin xyz="2.705701718e-09 1.027797597e-09 -1.067091013e-02"
                    rpy="0.000000000e+00 0.000000000e+00 0.000000000e+00"
            />
            <mass value="1.177975572e-01" />
            <inertia ixx="2.331594324e-05" iyy="5.547111616e-05" izz="6.418425544e-05"
                     ixy="1.186275510e-19" ixz="-5.081617394e-12" iyz="2.987434825e-19"
            />
        </inertial>
        <visual>
            <origin xyz="0.000000000e+00 0.000000000e+00 0.000000000e+00"
                    rpy="0.000000000e+00 0.000000000e+00 0.000000000e+00"
            />
            <geometry>
                <mesh filename="../meshes/mfl4_foot.stl" scale="1.000000000e-03 1.000000000e-03 1.000000000e-03" />
            </geometry>
            <material name="rubber_foot" />
        </visual>
        <collision>
            <origin xyz="0.000000000e+00 0.000000000e+00 0.000000000e+00"
                    rpy="0.000000000e+00 0.000000000e+00 0.000000000e+00"
            />
            <geometry>
                <mesh filename="../meshes/mfl4_foot.stl" scale="1.000000000e-03 1.000000000e-03 1.000000000e-03" />
            </geometry>
        </collision>
    </link>
    <!-- front right leg -->
    <link name="Lfr1_hipr">
        <inertial>
            <origin xyz="7.294080098e-02 -3.134129651e-02 1.150631301e-03"
                    rpy="0.000000000e+00 0.000000000e+00 0.000000000e+00"
            />
            <mass value="2.427425827e+00" />
            <inertia ixx="2.545006116e-03" iyy="3.452659848e-03" izz="3.163154635e-03"
                     ixy="4.352991373e-04" ixz="4.054155031e-05" iyz="7.380179669e-06"
            />
        </inertial>
        <visual>
            <origin xyz="0.000000000e+00 0.000000000e+00 0.000000000e+00"
                    rpy="0.000000000e+00 0.000000000e+00 0.000000000e+00"
            />
            <geometry>
                <mesh filename="../meshes/mfr1_hipr.stl" scale="1.000000000e-03 1.000000000e-03 1.000000000e-03" />
            </geometry>
            <material name="main" />
        </visual>
        <collision>
            <origin xyz="0.000000000e+00 0.000000000e+00 0.000000000e+00"
                    rpy="0.000000000e+00 0.000000000e+00 0.000000000e+00"
            />
            <geometry>
                <mesh filename="../meshes/mfr1_hipr.stl" scale="1.000000000e-03 1.000000000e-03 1.000000000e-03" />
            </geometry>
        </collision>
    </link>
    <link name="Lfr2_hipp">
        <inertial>
            <origin xyz="-2.800474550e-03 -4.503664905e-02 -1.957866605e-01"
                    rpy="0.000000000e+00 0.000000000e+00 0.000000000e+00"
            />
            <mass value="2.594676132e+00" />
            <inertia ixx="2.316445597e-02" iyy="2.390444345e-02" izz="2.149994334e-03"
                     ixy="4.572061837e-05" ixz="6.132553685e-04" iyz="-2.473164305e-03"
            />
        </inertial>
        <visual>
            <origin xyz="0.000000000e+00 0.000000000e+00 0.000000000e+00"
                    rpy="0.000000000e+00 0.000000000e+00 0.000000000e+00"
            />
            <geometry>
                <mesh filename="../meshes/mfr2_hipp.stl" scale="1.000000000e-03 1.000000000e-03 1.000000000e-03" />
            </geometry>
            <material name="main" />
        </visual>
        <collision>
            <origin xyz="0.000000000e+00 0.000000000e+00 0.000000000e+00"
                    rpy="0.000000000e+00 0.000000000e+00 0.000000000e+00"
            />
            <geometry>
                <mesh filename="../meshes/mfr2_hipp.stl" scale="1.000000000e-03 1.000000000e-03 1.000000000e-03" />
            </geometry>
        </collision>
    </link>
    <link name="Lfr3_knee">
        <inertial>
            <origin xyz="2.426553040e-02 1.042500689e-02 -1.612786540e-01"
                    rpy="0.000000000e+00 0.000000000e+00 0.000000000e+00"
            />
            <mass value="6.285872656e-01" />
            <inertia ixx="1.035529743e-02" iyy="1.066728754e-02" izz="4.117758823e-04"
                     ixy="6.811917582e-06" ixz="9.613583732e-04" iyz="-4.584134837e-05"
            />
        </inertial>
        <visual>
            <origin xyz="0.000000000e+00 0.000000000e+00 0.000000000e+00"
                    rpy="0.000000000e+00 0.000000000e+00 0.000000000e+00"
            />
            <geometry>
                <mesh filename="../meshes/mfr3_knee.stl" scale="1.000000000e-03 1.000000000e-03 1.000000000e-03" />
            </geometry>
            <material name="main" />
        </visual>
        <collision>
            <origin xyz="0.000000000e+00 0.000000000e+00 0.000000000e+00"
                    rpy="0.000000000e+00 0.000000000e+00 0.000000000e+00"
            />
            <geometry>
                <mesh filename="../meshes/mfr3_knee.stl" scale="1.000000000e-03 1.000000000e-03 1.000000000e-03" />
            </geometry>
        </collision>
    </link>
    <link name="Lfr4_foot">
        <inertial>
            <origin xyz="2.705701718e-09 1.027797597e-09 -1.067091013e-02"
                    rpy="0.000000000e+00 0.000000000e+00 0.000000000e+00"
            />
            <mass value="1.177975572e-01" />
            <inertia ixx="2.331594324e-05" iyy="5.547111616e-05" izz="6.418425544e-05"
                     ixy="1.186275510e-19" ixz="-5.081617394e-12" iyz="2.987434825e-19"
            />
        </inertial>
        <visual>
            <origin xyz="0.000000000e+00 0.000000000e+00 0.000000000e+00"
                    rpy="0.000000000e+00 0.000000000e+00 0.000000000e+00"
            />
            <geometry>
                <mesh filename="../meshes/mfr4_foot.stl" scale="1.000000000e-03 1.000000000e-03 1.000000000e-03" />
            </geometry>
            <material name="rubber_foot" />
        </visual>
        <collision>
            <origin xyz="0.000000000e+00 0.000000000e+00 0.000000000e+00"
                    rpy="0.000000000e+00 0.000000000e+00 0.000000000e+00"
            />
            <geometry>
                <mesh filename="../meshes/mfr4_foot.stl" scale="1.000000000e-03 1.000000000e-03 1.000000000e-03" />
            </geometry>
        </collision>
    </link>
    <!-- rear left leg -->
    <link name="Lrl1_hipr">
        <inertial>
            <origin xyz="-7.294080098e-02 3.134129651e-02 1.150631301e-03"
                    rpy="0.000000000e+00 0.000000000e+00 0.000000000e+00"
            />
            <mass value="2.427425827e+00" />
            <inertia ixx="2.545006116e-03" iyy="3.452659848e-03" izz="3.163154635e-03"
                     ixy="4.352991373e-04" ixz="-4.054155031e-05" iyz="-7.380179669e-06"
            />
        </inertial>
        <visual>
            <origin xyz="0.000000000e+00 0.000000000e+00 0.000000000e+00"
                    rpy="0.000000000e+00 0.000000000e+00 0.000000000e+00"
            />
            <geometry>
                <mesh filename="../meshes/mrl1_hipr.stl" scale="1.000000000e-03 1.000000000e-03 1.000000000e-03" />
            </geometry>
            <material name="main" />
        </visual>
        <collision>
            <origin xyz="0.000000000e+00 0.000000000e+00 0.000000000e+00"
                    rpy="0.000000000e+00 0.000000000e+00 0.000000000e+00"
            />
            <geometry>
                <mesh filename="../meshes/mrl1_hipr.stl" scale="1.000000000e-03 1.000000000e-03 1.000000000e-03" />
            </geometry>
        </collision>
    </link>
    <link name="Lrl2_hipp">
        <inertial>
            <origin xyz="2.800474550e-03 4.503664905e-02 -1.957866605e-01"
                    rpy="0.000000000e+00 0.000000000e+00 0.000000000e+00"
            />
            <mass value="2.594676132e+00" />
            <inertia ixx="2.316445597e-02" iyy="2.390444345e-02" izz="2.149994334e-03"
                     ixy="4.572061837e-05" ixz="-6.132553685e-04" iyz="2.473164305e-03"
            />
        </inertial>
        <visual>
            <origin xyz="0.000000000e+00 0.000000000e+00 0.000000000e+00"
                    rpy="0.000000000e+00 0.000000000e+00 0.000000000e+00"
            />
            <geometry>
                <mesh filename="../meshes/mrl2_hipp.stl" scale="1.000000000e-03 1.000000000e-03 1.000000000e-03" />
            </geometry>
            <material name="main" />
        </visual>
        <collision>
            <origin xyz="0.000000000e+00 0.000000000e+00 0.000000000e+00"
                    rpy="0.000000000e+00 0.000000000e+00 0.000000000e+00"
            />
            <geometry>
                <mesh filename="../meshes/mrl2_hipp.stl" scale="1.000000000e-03 1.000000000e-03 1.000000000e-03" />
            </geometry>
        </collision>
    </link>
    <link name="Lrl3_knee">
        <inertial>
            <origin xyz="2.426553019e-02 -1.042500691e-02 -1.612786530e-01"
                    rpy="0.000000000e+00 0.000000000e+00 0.000000000e+00"
            />
            <mass value="6.285872676e-01" />
            <inertia ixx="1.035529753e-02" iyy="1.066728763e-02" izz="4.117758631e-04"
                     ixy="-6.811911601e-06" ixz="9.613583800e-04" iyz="4.584135263e-05"
            />
        </inertial>
        <visual>
            <origin xyz="0.000000000e+00 0.000000000e+00 0.000000000e+00"
                    rpy="0.000000000e+00 0.000000000e+00 0.000000000e+00"
            />
            <geometry>
                <mesh filename="../meshes/mrl3_knee.stl" scale="1.000000000e-03 1.000000000e-03 1.000000000e-03" />
            </geometry>
            <material name="main" />
        </visual>
        <collision>
            <origin xyz="0.000000000e+00 0.000000000e+00 0.000000000e+00"
                    rpy="0.000000000e+00 0.000000000e+00 0.000000000e+00"
            />
            <geometry>
                <mesh filename="../meshes/mrl3_knee.stl" scale="1.000000000e-03 1.000000000e-03 1.000000000e-03" />
            </geometry>
        </collision>
    </link>
    <link name="Lrl4_foot">
        <inertial>
            <origin xyz="2.705701718e-09 1.027797597e-09 -1.067091013e-02"
                    rpy="0.000000000e+00 0.000000000e+00 0.000000000e+00"
            />
            <mass value="1.177975572e-01" />
            <inertia ixx="2.331594324e-05" iyy="5.547111616e-05" izz="6.418425544e-05"
                     ixy="1.186275510e-19" ixz="-5.081617394e-12" iyz="2.987434825e-19"
            />
        </inertial>
        <visual>
            <origin xyz="0.000000000e+00 0.000000000e+00 0.000000000e+00"
                    rpy="0.000000000e+00 0.000000000e+00 0.000000000e+00"
            />
            <geometry>
                <mesh filename="../meshes/mrl4_foot.stl" scale="1.000000000e-03 1.000000000e-03 1.000000000e-03" />
            </geometry>
            <material name="rubber_foot" />
        </visual>
        <collision>
            <origin xyz="0.000000000e+00 0.000000000e+00 0.000000000e+00"
                    rpy="0.000000000e+00 0.000000000e+00 0.000000000e+00"
            />
            <geometry>
                <mesh filename="../meshes/mrl4_foot.stl" scale="1.000000000e-03 1.000000000e-03 1.000000000e-03" />
            </geometry>
        </collision>
    </link>
    <!-- rear right leg -->
    <link name="Lrr1_hipr">
        <inertial>
            <origin xyz="-7.294080095e-02 -3.134129647e-02 8.641283195e-04"
                    rpy="0.000000000e+00 0.000000000e+00 0.000000000e+00"
            />
            <mass value="2.427425827e+00" />
            <inertia ixx="2.546407316e-03" iyy="3.454061042e-03" izz="3.163154640e-03"
                     ixy="-4.352991409e-04" ixz="-4.536943161e-05" iyz="3.739923718e-05"
            />
        </inertial>
        <visual>
            <origin xyz="0.000000000e+00 0.000000000e+00 0.000000000e+00"
                    rpy="0.000000000e+00 0.000000000e+00 0.000000000e+00"
            />
            <geometry>
                <mesh filename="../meshes/mrr1_hipr.stl" scale="1.000000000e-03 1.000000000e-03 1.000000000e-03" />
            </geometry>
            <material name="main" />
        </visual>
        <collision>
            <origin xyz="0.000000000e+00 0.000000000e+00 0.000000000e+00"
                    rpy="0.000000000e+00 0.000000000e+00 0.000000000e+00"
            />
            <geometry>
                <mesh filename="../meshes/mrr1_hipr.stl" scale="1.000000000e-03 1.000000000e-03 1.000000000e-03" />
            </geometry>
        </collision>
    </link>
    <link name="Lrr2_hipp">
        <inertial>
            <origin xyz="2.532435474e-03 -4.503664901e-02 -1.957866607e-01"
                    rpy="0.000000000e+00 0.000000000e+00 0.000000000e+00"
            />
            <mass value="2.594676127e+00" />
            <inertia ixx="2.316445599e-02" iyy="2.390815237e-02" izz="2.153703155e-03"
                     ixy="-8.660442215e-05" ixz="-6.522667705e-04" iyz="-2.473164296e-03"
            />
        </inertial>
        <visual>
            <origin xyz="0.000000000e+00 0.000000000e+00 0.000000000e+00"
                    rpy="0.000000000e+00 0.000000000e+00 0.000000000e+00"
            />
            <geometry>
                <mesh filename="../meshes/mrr2_hipp.stl" scale="1.000000000e-03 1.000000000e-03 1.000000000e-03" />
            </geometry>
            <material name="main" />
        </visual>
        <collision>
            <origin xyz="0.000000000e+00 0.000000000e+00 0.000000000e+00"
                    rpy="0.000000000e+00 0.000000000e+00 0.000000000e+00"
            />
            <geometry>
                <mesh filename="../meshes/mrr2_hipp.stl" scale="1.000000000e-03 1.000000000e-03 1.000000000e-03" />
            </geometry>
        </collision>
    </link>
    <link name="Lrr3_knee">
        <inertial>
            <origin xyz="2.426553040e-02 1.042500689e-02 -1.612786540e-01"
                    rpy="0.000000000e+00 0.000000000e+00 0.000000000e+00"
            />
            <mass value="6.285872656e-01" />
            <inertia ixx="1.035529743e-02" iyy="1.066728754e-02" izz="4.117758823e-04"
                     ixy="6.811917582e-06" ixz="9.613583732e-04" iyz="-4.584134837e-05"
            />
        </inertial>
        <visual>
            <origin xyz="0.000000000e+00 0.000000000e+00 0.000000000e+00"
                    rpy="0.000000000e+00 0.000000000e+00 0.000000000e+00"
            />
            <geometry>
                <mesh filename="../meshes/mrr3_knee.stl" scale="1.000000000e-03 1.000000000e-03 1.000000000e-03" />
            </geometry>
            <material name="main" />
        </visual>
        <collision>
            <origin xyz="0.000000000e+00 0.000000000e+00 0.000000000e+00"
                    rpy="0.000000000e+00 0.000000000e+00 0.000000000e+00"
            />
            <geometry>
                <mesh filename="../meshes/mrr3_knee.stl" scale="1.000000000e-03 1.000000000e-03 1.000000000e-03" />
            </geometry>
        </collision>
    </link>
    <link name="Lrr4_foot">
        <inertial>
            <origin xyz="2.705701718e-09 1.027797597e-09 -1.067091013e-02"
                    rpy="0.000000000e+00 0.000000000e+00 0.000000000e+00"
            />
            <mass value="1.177975572e-01" />
            <inertia ixx="2.331594324e-05" iyy="5.547111616e-05" izz="6.418425544e-05"
                     ixy="1.186275510e-19" ixz="-5.081617394e-12" iyz="2.987434825e-19"
            />
        </inertial>
        <visual>
            <origin xyz="0.000000000e+00 0.000000000e+00 0.000000000e+00"
                    rpy="0.000000000e+00 0.000000000e+00 0.000000000e+00"
            />
            <geometry>
                <mesh filename="../meshes/mrr4_foot.stl" scale="1.000000000e-03 1.000000000e-03 1.000000000e-03" />
            </geometry>
            <material name="rubber_foot" />
        </visual>
        <collision>
            <origin xyz="0.000000000e+00 0.000000000e+00 0.000000000e+00"
                    rpy="0.000000000e+00 0.000000000e+00 0.000000000e+00"
            />
            <geometry>
                <mesh filename="../meshes/mrr4_foot.stl" scale="1.000000000e-03 1.000000000e-03 1.000000000e-03" />
            </geometry>
        </collision>
    </link>

    <!-- joint tags  -->
    <joint name="J_F_base_L0_torso" type="fixed">
        <origin xyz="0.000000000e+00 0.000000000e+00 0.000000000e+00"
                rpy="0.000000000e+00 0.000000000e+00 0.000000000e+00"
        />
        <parent link="F_base" />
        <child link="L0_torso" />
    </joint>
    <joint name="J_L0_torso_F_imu" type="fixed">
        <origin xyz="-5.329070518e-18 1.000000000e-02 1.370000000e-01"
                rpy="2.240066227e-47 1.329267295e-15 -1.685188701e-32"
        />
        <parent link="L0_torso" />
        <child link="F_imu" />
    </joint>
    <!-- front left leg -->
    <joint name="Jfl1_hipr" type="revolute">
        <origin xyz="2.450000000e-01 8.500000000e-02 9.500000000e-02"
                rpy="-5.089555117e-16 1.146468200e-15 1.776043292e-16"
        />
        <parent link="L0_torso" />
        <child link="Lfl1_hipr" />
        <axis xyz="1.000000000e+00 2.771430217e-16 6.917208495e-16" />
        <dynamics damping="1.000000000e-01" friction="1.000000000e-01"/>
        <limit lower="-0.4363323129985824" upper="0.6108652381980153" effort="120.0" velocity="16.54572130890624" />
    </joint>
    <joint name="Jfl2_hipp" type="revolute">
        <origin xyz="7.800000000e-02 7.100000000e-02 -2.220446049e-16"
                rpy="2.164959932e-16 2.023884669e-15 7.919364777e-16"
        />
        <parent link="Lfl1_hipr" />
        <child link="Lfl2_hipp" />
        <axis xyz="1.358118866e-15 1.000000000e+00 4.890402926e-16" />
        <dynamics damping="1.000000000e-01" friction="1.000000000e-01"/>
        <limit lower="-2.6179938779914944" upper="2.6179938779914944" effort="120.0" velocity="16.54572130890624" />
    </joint>
    <joint name="Jfl3_knee" type="revolute">
        <origin xyz="-3.885780586e-16 2.100000000e-02 -2.500000000e-01"
                rpy="-7.690840163e-16 2.260768239e-13 6.866005907e-16"
        />
        <parent link="Lfl2_hipp" />
        <child link="Lfl3_knee" />
        <axis xyz="-2.044719456e-15 -1.000000000e+00 -2.226590174e-16" />
        <dynamics damping="1.000000000e-01" friction="1.000000000e-01"/>
        <limit lower="-2.6179938779914944" upper="2.6179938779914944" effort="120.0" velocity="16.54572130890624" />
    </joint>
    <joint name="Jfl4_foot" type="fixed">
        <origin xyz="3.416585254e-02 -1.000000000e-02 -3.148109135e-01"
                rpy="1.187979310e-15 -2.277900091e-13 -1.756701522e-15"
        />
        <parent link="Lfl3_knee" />
        <child link="Lfl4_foot" />
    </joint>
    <!-- front right leg -->
    <joint name="Jfr1_hipr" type="revolute">
        <origin xyz="2.450000000e-01 -8.500000000e-02 9.500000000e-02"
                rpy="1.153974090e-31 5.080899612e-16 9.995142698e-17"
        />
        <parent link="L0_torso" />
        <child link="Lfr1_hipr" />
        <axis xyz="1.000000000e+00 -9.995142698e-17 -1.740310651e-16" />
        <dynamics damping="1.000000000e-01" friction="1.000000000e-01"/>
        <limit lower="-0.4363323129985824" upper="0.6108652381980153" effort="120.0" velocity="16.54572130890624" />
    </joint>
    <joint name="Jfr2_hipp" type="revolute">
        <origin xyz="7.800000000e-02 -7.100000000e-02 3.330669074e-16"
                rpy="1.442957234e-15 -1.889008416e-16 2.914781323e-16"
        />
        <parent link="Lfr1_hipr" />
        <child link="Lfr2_hipp" />
        <axis xyz="2.747042555e-16 -1.000000000e+00 1.442957234e-15" />
        <dynamics damping="1.000000000e-01" friction="1.000000000e-01"/>
        <limit lower="-2.6179938779914944" upper="2.6179938779914944" effort="120.0" velocity="16.54572130890624" />
    </joint>
    <joint name="Jfr3_knee" type="revolute">
        <origin xyz="3.885780586e-16 -2.100000000e-02 -2.500000000e-01"
                rpy="-6.932124762e-14 -3.540223670e-14 -3.541908824e-14"
        />
        <parent link="Lfr2_hipp" />
        <child link="Lfr3_knee" />
        <axis xyz="-3.580481480e-14 1.000000000e+00 6.926820635e-14" />
        <dynamics damping="1.000000000e-01" friction="1.000000000e-01"/>
        <limit lower="-2.6179938779914944" upper="2.6179938779914944" effort="120.0" velocity="16.54572130890624" />
    </joint>
    <joint name="Jfr4_foot" type="fixed">
        <origin xyz="3.416585253e-02 1.000000000e-02 -3.148109135e-01"
                rpy="3.458377824e-14 -1.207367539e-15 3.838675335e-16"
        />
        <parent link="Lfr3_knee" />
        <child link="Lfr4_foot" />
    </joint>
    <!-- rear left leg -->
    <joint name="Jrl1_hipr" type="revolute">
        <origin xyz="-2.450000000e-01 8.500000000e-02 9.500000000e-02"
                rpy="-5.551115123e-16 -5.080899612e-16 -6.772046903e-16"
        />
        <parent link="L0_torso" />
        <child link="Lrl1_hipr" />
        <axis xyz="-1.000000000e+00 2.322900115e-16 -1.740310651e-16" />
        <dynamics damping="1.000000000e-01" friction="1.000000000e-01"/>
        <limit lower="-0.4363323129985824" upper="0.6108652381980153" effort="120.0" velocity="16.54572130890624" />
    </joint>
    <joint name="Jrl2_hipp" type="revolute">
        <origin xyz="-7.800000000e-02 7.100000000e-02 2.359223927e-16"
                rpy="-3.182839204e-16 3.970676587e-16 6.717842184e-16"
        />
        <parent link="Lrl1_hipr" />
        <child link="Lrl2_hipp" />
        <axis xyz="1.056018306e-16 1.000000000e+00 3.182839204e-16" />
        <dynamics damping="1.000000000e-01" friction="1.000000000e-01"/>
        <limit lower="-2.6179938779914944" upper="2.6179938779914944" effort="120.0" velocity="16.54572130890624" />
    </joint>
    <joint name="Jrl3_knee" type="revolute">
        <origin xyz="-1.387778781e-15 2.100000000e-02 -2.500000000e-01"
                rpy="1.407693600e-16 2.775557562e-17 2.241423840e-15"
        />
        <parent link="Lrl2_hipp" />
        <child link="Lrl3_knee" />
        <axis xyz="-2.236003368e-15 -1.000000000e+00 2.448038698e-16" />
        <dynamics damping="1.000000000e-01" friction="1.000000000e-01"/>
        <limit lower="-2.6179938779914944" upper="2.6179938779914944" effort="120.0" velocity="16.54572130890624" />
    </joint>
    <joint name="Jrl4_foot" type="fixed">
        <origin xyz="3.416585253e-02 -1.000000000e-02 -3.148109135e-01"
                rpy="7.787657566e-16 -1.387778781e-15 -1.542424099e-15"
        />
        <parent link="Lrl3_knee" />
        <child link="Lrl4_foot" />
    </joint>
    <!-- rear right leg -->
    <joint name="Jrr1_hipr" type="revolute">
        <origin xyz="-2.450000000e-01 -8.500000000e-02 9.500000000e-02"
                rpy="-1.944703387e-16 6.021330634e-16 1.454360807e-15"
        />
        <parent link="L0_torso" />
        <child link="Lrr1_hipr" />
        <axis xyz="-1.000000000e+00 2.363855509e-15 -3.747593880e-16" />
        <dynamics damping="1.000000000e-01" friction="1.000000000e-01"/>
        <limit lower="-0.4363323129985824" upper="0.6108652381980153" effort="120.0" velocity="16.54572130890624" />
    </joint>
    <joint name="Jrr2_hipp" type="revolute">
        <origin xyz="-7.800000000e-02 -7.100000000e-02 3.330669074e-16"
                rpy="-4.130572104e-16 -8.373337576e-16 -2.695168968e-16"
        />
        <parent link="Lrr1_hipr" />
        <child link="Lrr2_hipp" />
        <axis xyz="-2.966654910e-16 -1.000000000e+00 -4.014701558e-16" />
        <dynamics damping="1.000000000e-01" friction="1.000000000e-01"/>
        <limit lower="-2.6179938779914944" upper="2.6179938779914944" effort="120.0" velocity="16.54572130890624" />
    </joint>
    <joint name="Jrr3_knee" type="revolute">
        <origin xyz="-1.110223025e-15 -2.100000000e-02 -2.500000000e-01"
                rpy="-3.336121182e-14 4.017341479e-16 -6.145287502e-16"
        />
        <parent link="Lrr2_hipp" />
        <child link="Lrr3_knee" />
        <axis xyz="4.030255562e-17 1.000000000e+00 -3.409086390e-14" />
        <dynamics damping="1.000000000e-01" friction="1.000000000e-01"/>
        <limit lower="-2.6179938779914944" upper="2.6179938779914944" effort="120.0" velocity="16.54572130890624" />
    </joint>
    <joint name="Jrr4_foot" type="fixed">
        <origin xyz="3.416585253e-02 1.000000000e-02 -3.148109135e-01"
                rpy="3.401487905e-14 1.221245327e-15 1.232641083e-16"
        />
        <parent link="Lrr3_knee" />
        <child link="Lrr4_foot" />
    </joint>

</robot>
