<mujoco model="Xtellar.Robotics/ToGo.Prototype">
    <compiler meshdir="../meshes" />

    <default>
        <default class="viscol">
            <geom
                type="mesh" rgba="0.7529411764705882 0.7529411764705882 0.7529411764705882 1.0"
                contype="1" conaffinity="1" density="0"
                solref="0.005 1" solimp="0.95 0.99 0.001 0.5 2"
            />
        </default>
        <default class="rubber_wheel">
            <geom
                type="mesh" rgba="0.7529411764705882 0.7529411764705882 0.7529411764705882 1.0"
                contype="1" conaffinity="1" density="0"
                solref="0.005 1" solimp="0.95 0.99 0.001 0.5 2"
                condim="6" friction="1.5 0.02 0.001"
            />
        </default>
    </default>

    <asset>
        <!-- body meshes -->
        <mesh name="mesh_body_front"     file="l0_body_front.stl"  scale="0.001 0.001 0.001" />
        <mesh name="mesh_body_rear"      file="l1_body_rear.stl"   scale="0.001 0.001 0.001" />

        <!-- front left leg meshes -->
        <mesh name="mesh_lfl1_hip_roll"  file="lfl1_hip_roll.stl"  scale="0.001 0.001 0.001" />
        <mesh name="mesh_lfl2_hip_pitch" file="lfl2_hip_pitch.stl" scale="0.001 0.001 0.001" />
        <mesh name="mesh_lfl3_knee"      file="lfl3_knee.stl"      scale="0.001 0.001 0.001" />
        <mesh name="mesh_lfl4_wheel"     file="lfl4_wheel.stl"     scale="0.001 0.001 0.001" />

        <!-- front right leg meshes -->
        <mesh name="mesh_lfr1_hip_roll"  file="lfr1_hip_roll.stl"  scale="0.001 0.001 0.001" />
        <mesh name="mesh_lfr2_hip_pitch" file="lfr2_hip_pitch.stl" scale="0.001 0.001 0.001" />
        <mesh name="mesh_lfr3_knee"      file="lfr3_knee.stl"      scale="0.001 0.001 0.001" />
        <mesh name="mesh_lfr4_wheel"     file="lfr4_wheel.stl"     scale="0.001 0.001 0.001" />

        <!-- rear left leg meshes -->
        <mesh name="mesh_lrl1_hip_roll"  file="lrl1_hip_roll.stl"  scale="0.001 0.001 0.001" />
        <mesh name="mesh_lrl2_hip_pitch" file="lrl2_hip_pitch.stl" scale="0.001 0.001 0.001" />
        <mesh name="mesh_lrl3_knee"      file="lrl3_knee.stl"      scale="0.001 0.001 0.001" />
        <mesh name="mesh_lrl4_wheel"     file="lrl4_wheel.stl"     scale="0.001 0.001 0.001" />

        <!-- rear right leg meshes -->
        <mesh name="mesh_lrr1_hip_roll"  file="lrr1_hip_roll.stl"  scale="0.001 0.001 0.001" />
        <mesh name="mesh_lrr2_hip_pitch" file="lrr2_hip_pitch.stl" scale="0.001 0.001 0.001" />
        <mesh name="mesh_lrr3_knee"      file="lrr3_knee.stl"      scale="0.001 0.001 0.001" />
        <mesh name="mesh_lrr4_wheel"     file="lrr4_wheel.stl"     scale="0.001 0.001 0.001" />
    </asset>

    <worldbody>
        <!-- robot floating base (root) -->
        <body
            name="F_base"
            pos="0.000000000e+00 0.000000000e+00 0.000000000e+00"
            euler="0.000000000e+00 0.000000000e+00 0.000000000e+00"
        >

            <!-- front body -->
            <body
                name="L0_body_front"
                pos="0.000000000e+00 0.000000000e+00 2.000000000e-01"
                euler="-0.000000000e+00 9.000000000e+01 9.000000000e+01"
            >
                <inertial
                    pos="-2.160440278e-03 7.391865019e-02 7.675965061e-02"
                    mass="1.139659386e+01"
                    fullinertia="1.365484540e-01 2.028016259e-01 9.378844195e-02 1.099460117e-05 -5.270341860e-04 5.332965063e-03"
                />
                <geom class="viscol" mesh="mesh_body_front" />

                <site name="imu" pos="0 0.13 0.05" euler="-90 0 -90" />

                <!-- front left leg -->
                <body
                    name="Lfl1_hip_roll"
                    pos="9.000000000e-02 7.500000000e-02 1.870000000e-01"
                    euler="-0.000000000e+00 0.000000000e+00 -0.000000000e+00"
                >
                    <joint
                        name="Jfl1_hip_roll"
                        type="hinge"
                        axis="0 0 1"
                        range="-6.000000000e+01 6.000000000e+01"
                        armature="0.05"
                        damping="0.027"
                        frictionloss="0.1"
                    />
                    <inertial
                        pos="-7.218781934e-04 5.949582956e-04 7.162279484e-02"
                        mass="1.887043626e+00"
                        fullinertia="3.748543127e-03 2.915061831e-03 2.089010486e-03 3.359890495e-05 -2.521507038e-05 -2.475313699e-05"
                    />
                    <geom class="viscol" mesh="mesh_lfl1_hip_roll" />

                    <body
                        name="Lfl2_hip_pitch"
                        pos="2.600000000e-02 0.000000000e+00 7.300000000e-02"
                        euler="-0.000000000e+00 0.000000000e+00 -0.000000000e+00"
                    >
                        <joint
                            name="Jfl2_hip_pitch"
                            type="hinge"
                            axis="1 0 0"
                            range="-9.000000000e+01 9.000000000e+01"
                            armature="0.05"
                            damping="0.027"
                            frictionloss="0.1"
                        />
                        <inertial
                            pos="6.346748536e-02 4.844918472e-03 -4.638462066e-02"
                            mass="3.023532673e+00"
                            fullinertia="3.172443996e-02 3.242234462e-02 6.362320073e-03 -5.838623889e-04 5.373137003e-03 1.632961065e-03"
                        />
                        <geom class="viscol" mesh="mesh_lfl2_hip_pitch" />

                        <body
                            name="Lfl3_knee"
                            pos="1.059700000e-01 0.000000000e+00 -3.000000000e-01"
                            euler="-0.000000000e+00 0.000000000e+00 -0.000000000e+00"
                        >
                            <joint
                                name="Jfl3_knee"
                                type="hinge"
                                axis="1 0 0"
                                range="-1.000000000e+01 9.000000000e+01"
                                armature="0.05"
                                damping="0.027"
                                frictionloss="0.1"
                            />
                            <inertial
                                pos="1.263152507e-02 -1.463381461e-01 1.896785452e-01"
                                mass="1.590219164e+00"
                                fullinertia="1.987810147e-02 1.249170801e-02 8.346688455e-03 8.375368726e-04 -1.012803121e-03 8.824097408e-03"
                            />
                            <geom class="viscol" mesh="mesh_lfl3_knee" />

                            <body
                                name="Lfl4_wheel"
                                pos="5.130000000e-02 -1.846984332e-01 2.364032334e-01"
                                euler="-0.000000000e+00 0.000000000e+00 -0.000000000e+00"
                            >
                                <inertial
                                    pos="9.771946597e-03 4.078350782e-09 -1.664886526e-08"
                                    mass="1.292573765e+00"
                                    fullinertia="5.526587828e-03 2.904900666e-03 2.904865502e-03 9.806179590e-14 1.929721917e-13 7.217850448e-24"
                                />
                                <geom class="rubber_wheel" mesh="mesh_lfl4_wheel" />
                            </body>
                        </body>
                    </body>
                </body>
                <!-- end of front left leg -->

                <!-- front right leg -->
                <body
                    name="Lfr1_hip_roll"
                    pos="-9.000000000e-02 7.500000000e-02 1.870000000e-01"
                    euler="-0.000000000e+00 0.000000000e+00 -0.000000000e+00"
                >
                    <joint
                        name="Jfr1_hip_roll"
                        type="hinge"
                        axis="0 0 1"
                        range="-6.000000000e+01 6.000000000e+01"
                        armature="0.05"
                        damping="0.027"
                        frictionloss="0.1"
                    />
                    <inertial
                        pos="7.144685036e-04 5.962087688e-04 7.137999600e-02"
                        mass="1.894140161e+00"
                        fullinertia="3.779979220e-03 2.947083450e-03 2.092282368e-03 -3.345744103e-05 2.512586225e-05 -2.472469088e-05"
                    />
                    <geom class="viscol" mesh="mesh_lfr1_hip_roll" />

                    <body
                        name="Lfr2_hip_pitch"
                        pos="-2.600000000e-02 0.000000000e+00 7.300000000e-02"
                        euler="-0.000000000e+00 0.000000000e+00 -0.000000000e+00"
                    >
                        <joint
                            name="Jfr2_hip_pitch"
                            type="hinge"
                            axis="-1 0 0"
                            range="-9.000000000e+01 9.000000000e+01"
                            armature="0.05"
                            damping="0.027"
                            frictionloss="0.1"
                        />
                        <inertial
                            pos="-6.347362217e-02 4.845879513e-03 -4.638229906e-02"
                            mass="3.023536580e+00"
                            fullinertia="3.172086952e-02 3.242099324e-02 6.364486562e-03 5.838902334e-04 -5.374138070e-03 1.632835155e-03"
                        />
                        <geom class="viscol" mesh="mesh_lfr2_hip_pitch" />

                        <body
                            name="Lfr3_knee"
                            pos="-1.060000000e-01 0.000000000e+00 -3.000000000e-01"
                            euler="-0.000000000e+00 0.000000000e+00 -0.000000000e+00"
                        >
                            <joint
                                name="Jfr3_knee"
                                type="hinge"
                                axis="-1 0 0"
                                range="-9.000000000e+01 1.000000000e+01"
                                armature="0.05"
                                damping="0.027"
                                frictionloss="0.1"
                            />
                            <inertial
                                pos="-1.263152424e-02 -1.462987283e-01 1.897041425e-01"
                                mass="1.590219198e+00"
                                fullinertia="1.987709300e-02 1.249560477e-02 8.341783311e-03 -8.387570080e-04 1.012010778e-03 8.822690073e-03"
                            />
                            <geom class="viscol" mesh="mesh_lfr3_knee" />

                            <body
                                name="Lfr4_wheel"
                                pos="-5.130000000e-02 -1.846984426e-01 2.364032261e-01"
                                euler="-0.000000000e+00 0.000000000e+00 -0.000000000e+00"
                            >
                                <inertial
                                    pos="-9.771946597e-03 1.049721249e-08 1.355106480e-08"
                                    mass="1.292573765e+00"
                                    fullinertia="5.526587828e-03 2.904903074e-03 2.904863094e-03 8.384166721e-19 3.216355069e-19 -2.465190329e-32"
                                />
                                <geom class="rubber_wheel" mesh="mesh_lfr4_wheel" />
                            </body>
                        </body>
                    </body>
                </body>
                <!-- end of front right leg -->
                
                <!-- rear body -->
                <body
                    name="L1_body_rear"
                    pos="0.000000000e+00 3.325000000e-02 -8.000000000e-02"
                    euler="-0.000000000e+00 0.000000000e+00 -0.000000000e+00"
                >
                    <inertial
                        pos="1.084473223e-18 3.608465643e-02 -9.648547249e-02"
                        mass="4.536476336e+00"
                        fullinertia="2.288950781e-02 4.963913835e-02 3.595594733e-02 3.489794068e-06 0.000000000e+00 -1.420369757e-03"
                    />
                    <geom class="viscol" mesh="mesh_body_rear" />

                    <!-- rear left leg -->
                    <body
                        name="Lrl1_hip_roll"
                        pos="9.000000000e-02 4.175000000e-02 -1.070000000e-01"
                        euler="-0.000000000e+00 0.000000000e+00 -0.000000000e+00"
                    >
                        <joint
                            name="Jrl1_hip_roll"
                            type="hinge"
                            axis="0 0 -1"
                            range="-6.000000000e+01 6.000000000e+01"
                            armature="0.05"
                            damping="0.027"
                            frictionloss="0.1"
                        />
                        <inertial
                            pos="-7.144685036e-04 5.962087688e-04 -7.137999600e-02"
                            mass="1.894140161e+00"
                            fullinertia="3.779979220e-03 2.947083450e-03 2.092282368e-03 3.345744103e-05 2.512586225e-05 2.472469088e-05"
                        />
                        <geom class="viscol" mesh="mesh_lrl1_hip_roll" />

                        <body
                            name="Lrl2_hip_pitch"
                            pos="2.600000000e-02 0.000000000e+00 -7.300000000e-02"
                            euler="-0.000000000e+00 0.000000000e+00 -0.000000000e+00"
                        >
                            <joint
                                name="Jrl2_hip_pitch"
                                type="hinge"
                                axis="1 0 0"
                                range="-9.000000000e+01 9.000000000e+01"
                                armature="0.05"
                                damping="0.027"
                                frictionloss="0.1"
                            />
                            <inertial
                                pos="6.346748536e-02 4.845918553e-03 -4.464742773e-02"
                                mass="3.023532673e+00"
                                fullinertia="3.220255281e-02 3.290048678e-02 6.362290769e-03 -5.837432177e-04 5.588807339e-03 1.658273799e-03"
                            />
                            <geom class="viscol" mesh="mesh_lrl2_hip_pitch" />

                            <body
                                name="Lrl3_knee"
                                pos="1.060000000e-01 0.000000000e+00 -3.000000000e-01"
                                euler="-0.000000000e+00 0.000000000e+00 -0.000000000e+00"
                            >
                                <joint
                                    name="Jrl3_knee"
                                    type="hinge"
                                    axis="1 0 0"
                                    range="-1.000000000e+01 9.000000000e+01"
                                    armature="0.05"
                                    damping="0.027"
                                    frictionloss="0.1"
                                />
                                <inertial
                                    pos="1.263152507e-02 -1.463381536e-01 1.896785394e-01"
                                    mass="1.590219164e+00"
                                    fullinertia="1.987810147e-02 1.249170731e-02 8.346689155e-03 8.375369127e-04 -1.012803088e-03 8.824097573e-03"
                                />
                                <geom class="viscol" mesh="mesh_lrl3_knee" />

                                <body
                                    name="Lrl4_wheel"
                                    pos="5.130000000e-02 -1.846984426e-01 2.364032261e-01"
                                    euler="-0.000000000e+00 0.000000000e+00 -0.000000000e+00"
                                >
                                    <inertial
                                        pos="9.771946596e-03 -4.792935021e-09 -1.645753933e-08"
                                        mass="1.292573765e+00"
                                        fullinertia="5.526587829e-03 2.904882290e-03 2.904883879e-03 -1.112179803e-15 -1.668933033e-15 7.080026624e-28"
                                    />
                                    <geom class="rubber_wheel" mesh="mesh_lrl4_wheel" />
                                </body>
                            </body>
                        </body>
                    </body>
                    <!-- end of rear left leg -->

                    <!-- rear right leg -->
                    <body
                        name="Lrr1_hip_roll"
                        pos="-9.000000000e-02 4.175000000e-02 -1.070000000e-01"
                        euler="-0.000000000e+00 0.000000000e+00 -0.000000000e+00"
                    >
                        <joint
                            name="Jrr1_hip_roll"
                            type="hinge"
                            axis="0 0 -1"
                            range="-6.000000000e+01 6.000000000e+01"
                            armature="0.05"
                            damping="0.027"
                            frictionloss="0.1"
                        />
                        <inertial
                            pos="7.218781934e-04 5.949582956e-04 -7.162279484e-02"
                            mass="1.887043626e+00"
                            fullinertia="3.748543127e-03 2.915061831e-03 2.089010486e-03 -3.359890495e-05 -2.521507038e-05 2.475313699e-05"
                        />
                        <geom class="viscol" mesh="mesh_lrr1_hip_roll" />

                        <body
                            name="Lrr2_hip_pitch"
                            pos="-2.600000000e-02 0.000000000e+00 -7.300000000e-02"
                            euler="-0.000000000e+00 0.000000000e+00 -0.000000000e+00"
                        >
                            <joint
                                name="Jrr2_hip_pitch"
                                type="hinge"
                                axis="-1 0 0"
                                range="-9.000000000e+01 9.000000000e+01"
                                armature="0.05"
                                damping="0.027"
                                frictionloss="0.1"
                            />
                            <inertial
                                pos="-6.347362217e-02 4.844880184e-03 -4.464510837e-02"
                                mass="3.023536580e+00"
                                fullinertia="3.219901671e-02 3.289911101e-02 6.364515980e-03 5.840095199e-04 -5.589840639e-03 1.658423400e-03"
                            />
                            <geom class="viscol" mesh="mesh_lrr2_hip_pitch" />

                            <body
                                name="Lrr3_knee"
                                pos="-1.060000000e-01 0.000000000e+00 -3.000000000e-01"
                                euler="-0.000000000e+00 0.000000000e+00 -0.000000000e+00"
                            >
                                <joint
                                    name="Jrr3_knee"
                                    type="hinge"
                                    axis="-1 0 0"
                                    range="-9.000000000e+01 1.000000000e+01"
                                    armature="0.05"
                                    damping="0.027"
                                    frictionloss="0.1"
                                />
                                <inertial
                                    pos="-1.270152424e-02 -1.462987283e-01 1.897041425e-01"
                                    mass="1.590219198e+00"
                                    fullinertia="1.987709300e-02 1.249560477e-02 8.341783311e-03 -8.387570080e-04 1.012010778e-03 8.822690073e-03"
                                />
                                <geom class="viscol" mesh="mesh_lrr3_knee" />

                                <body
                                    name="Lrr4_wheel"
                                    pos="-5.137000000e-02 -1.846984426e-01 2.364032261e-01"
                                    euler="-0.000000000e+00 0.000000000e+00 -0.000000000e+00"
                                >
                                    <inertial
                                        pos="-9.771946596e-03 -1.586638509e-08 -6.486960136e-09"
                                        mass="1.292573765e+00"
                                        fullinertia="5.526587829e-03 2.904888178e-03 2.904877991e-03 -1.801139669e-18 -1.207949219e-18 0.000000000e+00"
                                    />
                                    <geom class="rubber_wheel" mesh="mesh_lrr4_wheel" />
                                </body>
                            </body>
                        </body>
                    </body>
                    <!-- end of rear right leg -->
                </body>
                <!-- end of rear body -->
            </body>
            <!-- end of front body -->
        </body>
        <!-- robot floating base (root) -->
    </worldbody>

    <contact>
        <exclude body1="L0_body_front"  body2="Lfl1_hip_roll" />
        <exclude body1="L0_body_front"  body2="Lfl2_hip_pitch" />
        <exclude body1="L0_body_front"  body2="Lfr1_hip_roll" />
        <exclude body1="L0_body_front"  body2="Lfr2_hip_pitch" />
        <exclude body1="L0_body_front"  body2="L1_body_rear" />
        <exclude body1="L1_body_rear"   body2="Lrl1_hip_roll" />
        <exclude body1="L1_body_rear"   body2="Lrl2_hip_pitch" />
        <exclude body1="L1_body_rear"   body2="Lrr1_hip_roll" />
        <exclude body1="L1_body_rear"   body2="Lrr2_hip_pitch" />
    </contact>

    <actuator>
        <!-- front left leg -->
        <motor
            name="Rfl1_hip_roll" joint="Jfl1_hip_roll" gear="1"
            ctrlrange="-1.500000000e+02 1.500000000e+02"
            forcerange="-1.500000000e+02 1.500000000e+02"
        />
        <motor
            name="Rfl2_hip_pitch" joint="Jfl2_hip_pitch" gear="1"
            ctrlrange="-1.500000000e+02 1.500000000e+02"
            forcerange="-1.500000000e+02 1.500000000e+02"
        />
        <motor
            name="Rfl3_knee" joint="Jfl3_knee" gear="1"
            ctrlrange="-1.500000000e+02 1.500000000e+02"
            forcerange="-1.500000000e+02 1.500000000e+02"
        />
        <!-- front right leg -->
        <motor
            name="Rfr1_hip_roll" joint="Jfr1_hip_roll" gear="1"
            ctrlrange="-1.500000000e+02 1.500000000e+02"
            forcerange="-1.500000000e+02 1.500000000e+02"
        />
        <motor
            name="Rfr2_hip_pitch" joint="Jfr2_hip_pitch" gear="1"
            ctrlrange="-1.500000000e+02 1.500000000e+02"
            forcerange="-1.500000000e+02 1.500000000e+02"
        />
        <motor
            name="Rfr3_knee" joint="Jfr3_knee" gear="1"
            ctrlrange="-1.500000000e+02 1.500000000e+02"
            forcerange="-1.500000000e+02 1.500000000e+02"
        />
        <!-- rear left leg -->
        <motor
            name="Rrl1_hip_roll" joint="Jrl1_hip_roll" gear="1"
            ctrlrange="-1.500000000e+02 1.500000000e+02"
            forcerange="-1.500000000e+02 1.500000000e+02"
        />
        <motor
            name="Rrl2_hip_pitch" joint="Jrl2_hip_pitch" gear="1"
            ctrlrange="-1.500000000e+02 1.500000000e+02"
            forcerange="-1.500000000e+02 1.500000000e+02"
        />
        <motor
            name="Rrl3_knee" joint="Jrl3_knee" gear="1"
            ctrlrange="-1.500000000e+02 1.500000000e+02"
            forcerange="-1.500000000e+02 1.500000000e+02"
        />
        <!-- rear right leg -->
        <motor
            name="Rrr1_hip_roll" joint="Jrr1_hip_roll" gear="1"
            ctrlrange="-1.500000000e+02 1.500000000e+02"
            forcerange="-1.500000000e+02 1.500000000e+02"
        />
        <motor
            name="Rrr2_hip_pitch" joint="Jrr2_hip_pitch" gear="1"
            ctrlrange="-1.500000000e+02 1.500000000e+02"
            forcerange="-1.500000000e+02 1.500000000e+02"
        />
        <motor
            name="Rrr3_knee" joint="Jrr3_knee" gear="1"
            ctrlrange="-1.500000000e+02 1.500000000e+02"
            forcerange="-1.500000000e+02 1.500000000e+02"
        />
    </actuator>
    
    <sensor>
        <!-- joint position `q_J` -->
        <!-- front left leg -->
        <jointpos name="q_Jfl1_hip_roll"  joint="Jfl1_hip_roll"     noise="0.000" />
        <jointpos name="q_Jfl2_hip_pitch" joint="Jfl2_hip_pitch"    noise="0.000" />
        <jointpos name="q_Jfl3_knee"      joint="Jfl3_knee"         noise="0.000" />

        <!-- front right leg -->
        <jointpos name="q_Jfr1_hip_roll"  joint="Jfr1_hip_roll"     noise="0.000" />
        <jointpos name="q_Jfr2_hip_pitch" joint="Jfr2_hip_pitch"    noise="0.000" />
        <jointpos name="q_Jfr3_knee"      joint="Jfr3_knee"         noise="0.000" />

        <!-- rear left leg -->
        <jointpos name="q_Jrl1_hip_roll"  joint="Jrl1_hip_roll"     noise="0.000" />
        <jointpos name="q_Jrl2_hip_pitch" joint="Jrl2_hip_pitch"    noise="0.000" />
        <jointpos name="q_Jrl3_knee"      joint="Jrl3_knee"         noise="0.000" />

        <!-- rear right leg -->
        <jointpos name="q_Jrr1_hip_roll"  joint="Jrr1_hip_roll"     noise="0.000" />
        <jointpos name="q_Jrr2_hip_pitch" joint="Jrr2_hip_pitch"    noise="0.000" />
        <jointpos name="q_Jrr3_knee"      joint="Jrr3_knee"         noise="0.000" />

        <!-- joint velocity `dq_J` -->
        <!-- front left leg -->
        <jointvel name="dq_Jfl1_hip_roll"  joint="Jfl1_hip_roll"    noise="0.000" />
        <jointvel name="dq_Jfl2_hip_pitch" joint="Jfl2_hip_pitch"   noise="0.000" />
        <jointvel name="dq_Jfl3_knee"      joint="Jfl3_knee"        noise="0.000" />

        <!-- front right leg -->
        <jointvel name="dq_Jfr1_hip_roll"  joint="Jfr1_hip_roll"    noise="0.000" />
        <jointvel name="dq_Jfr2_hip_pitch" joint="Jfr2_hip_pitch"   noise="0.000" />
        <jointvel name="dq_Jfr3_knee"      joint="Jfr3_knee"        noise="0.000" />

        <!-- rear left leg -->
        <jointvel name="dq_Jrl1_hip_roll"  joint="Jrl1_hip_roll"    noise="0.000" />
        <jointvel name="dq_Jrl2_hip_pitch" joint="Jrl2_hip_pitch"   noise="0.000" />
        <jointvel name="dq_Jrl3_knee"      joint="Jrl3_knee"        noise="0.000" />

        <!-- rear right leg -->
        <jointvel name="dq_Jrr1_hip_roll"  joint="Jrr1_hip_roll"    noise="0.000" />
        <jointvel name="dq_Jrr2_hip_pitch" joint="Jrr2_hip_pitch"   noise="0.000" />
        <jointvel name="dq_Jrr3_knee"      joint="Jrr3_knee"        noise="0.000" />

        <!-- joint torque `tau_J` -->
        <!-- front left leg -->
        <jointactuatorfrc name="tau_Jfl1_hip_roll"  joint="Jfl1_hip_roll"   noise="0.000" />
        <jointactuatorfrc name="tau_Jfl2_hip_pitch" joint="Jfl2_hip_pitch"  noise="0.000" />
        <jointactuatorfrc name="tau_Jfl3_knee"      joint="Jfl3_knee"       noise="0.000" />

        <!-- front right leg -->
        <jointactuatorfrc name="tau_Jfr1_hip_roll"  joint="Jfr1_hip_roll"   noise="0.000"/>
        <jointactuatorfrc name="tau_Jfr2_hip_pitch" joint="Jfr2_hip_pitch"  noise="0.000"/>
        <jointactuatorfrc name="tau_Jfr3_knee"      joint="Jfr3_knee"       noise="0.000"/>

        <!-- rear left leg -->
        <jointactuatorfrc name="tau_Jrl1_hip_roll"  joint="Jrl1_hip_roll"   noise="0.000"/>
        <jointactuatorfrc name="tau_Jrl2_hip_pitch" joint="Jrl2_hip_pitch"  noise="0.000"/>
        <jointactuatorfrc name="tau_Jrl3_knee"      joint="Jrl3_knee"       noise="0.000"/>

        <!-- rear right leg -->
        <jointactuatorfrc name="tau_Jrr1_hip_roll"  joint="Jrr1_hip_roll"   noise="0.000"/>
        <jointactuatorfrc name="tau_Jrr2_hip_pitch" joint="Jrr2_hip_pitch"  noise="0.000"/>
        <jointactuatorfrc name="tau_Jrr3_knee"      joint="Jrr3_knee"       noise="0.000"/>

        <!-- IMU -->
        <gyro           name="imu_gyro" site="imu" noise="0.000" />
        <accelerometer  name="imu_accl" site="imu" noise="0.000" />
        <framequat      name="imu_quat" objtype="site" objname="imu" noise="0.000" />
        <framepos       name="gt_pos"   objtype="site" objname="imu" />
        <framelinvel    name="gt_vel"   objtype="site" objname="imu" />
    </sensor>

</mujoco>
